<?xml version="1.0" encoding="utf-8"?>
<!-- This URDF was automatically created by SolidWorks to URDF Exporter! Originally created by Stephen Brawner (brawner@gmail.com) 
     Commit Version: 1.6.0-4-g7f85cfe  Build Version: 1.6.7995.38578
     For more information, please see http://wiki.ros.org/sw_urdf_exporter -->
<robot
  name="my_robot">


 <link name="world" />



  <link
    name="base_link">
    <inertial>
      <origin
        xyz="0.0028436 -0.034039 4.0565E-05"
        rpy="0 0 0" />
      <mass
        value="500.1" />
      <inertia
        ixx="0.31782"
        ixy="-0.209"
        ixz="0.00045539"
        iyy="0.83341"
        iyz="0.00020479"
        izz="1.0223" />
    </inertial>
    <visual>
      <origin
        xyz="0 0 0"
        rpy="0 0 0" />
      <geometry>
        <mesh
          filename="package://my_robot/meshes/base_link.STL"/>
      </geometry>
      <material
        name="">
        <color
          rgba="0.57255 0.57647 0.57647 1" />
      </material>
    </visual>
    <collision>
      <origin
        xyz="0 0 0"
        rpy="0 0 0" />
      <geometry>
        <mesh
          filename="package://my_robot/meshes/base_link.STL" />
      </geometry>
    </collision>
  </link>

  <joint name="world_to_base" type="fixed">
  <parent link="world"/>
  <child link="base_link"/>
  <origin xyz="0 0 1" rpy="0 0 0"/>
</joint>


  <link
    name="link_f_r">
    <inertial>
      <origin
        xyz="-2.88657979602425E-08 -0.0277269266239377 0.0157057560395292"
        rpy="0 0 0" />
      <mass
        value="30" />
      <inertia
        ixx="3.64634346445373E-05"
        ixy="3.57731733676339E-11"
        ixz="2.13056608406061E-11"
        iyy="3.41959117675972E-05"
        iyz="2.07855922549413E-06"
        izz="8.8093054111005E-06" />
    </inertial>
    <visual>
      <origin
        xyz="0 0 0"
        rpy="0 0 0" />
      <geometry>
        <mesh
          filename="package://my_robot/meshes/link_f_r.STL" />
      </geometry>
      <material
        name="">
        <color
          rgba="0.776470588235294 0.776470588235294 0.819607843137255 1" />
      </material>
    </visual>
    <collision>
      <origin
        xyz="0 0 0"
        rpy="0 0 0" />
      <geometry>
        <mesh
          filename="package://my_robot/meshes/link_f_r.STL" />
      </geometry>
    </collision>
  </link>
  <joint
    name="joint_f_r"
    type="revolute">
    <origin
      xyz="-0.11936 0.03 -0.083652"
      rpy="1.5708 0 3.1403" />
    <parent
      link="base_link" />
    <child
      link="link_f_r" />
    <axis
      xyz="0 1 0" />
    <limit
      lower="0"
      upper="0"
      effort="0"
      velocity="0" />
  </joint>
  <link
    name="link_f_r_w">
    <inertial>
      <origin
        xyz="-3.48050477327888E-11 -3.49514064912348E-09 0.0193015459055894"
        rpy="0 0 0" />
      <mass
        value="50" />
      <inertia
        ixx="0.00328931016603337"
        ixy="3.89005920147955E-11"
        ixz="1.12954391005008E-11"
        iyy="0.00328931075597657"
        iyz="5.98754600007619E-11"
        izz="0.00610927992549753" />
    </inertial>
    <visual>
      <origin
        xyz="0 0 0"
        rpy="0 0 0" />
      <geometry>
        <mesh
          filename="package://my_robot/meshes/link_f_r_w.STL" />
      </geometry>
      <material
        name="">
        <color
          rgba="0.43921568627451 0.411764705882353 0.411764705882353 1" />
      </material>
    </visual>
    <collision>
      <origin
        xyz="0 0 0"
        rpy="0 0 0" />
      <geometry>
        <mesh
          filename="package://my_robot/meshes/link_f_r_w.STL" />
      </geometry>
    </collision>
  </link>
  <joint
    name="joint_f_r_w"
    type="continuous">
    <origin
      xyz="0 -0.0287 0.0315"
      rpy="0 0 -1.5393" />
    <parent
      link="link_f_r" />
    <child
      link="link_f_r_w" />
    <axis
      xyz="0 0 1" />
  </joint>
  <link
    name="link_f_l">
    <inertial>
      <origin
        xyz="-2.88657978908535E-08 -0.0277269266239377 0.0157057560395293"
        rpy="0 0 0" />
      <mass
        value="30" />
      <inertia
        ixx="3.64634346445373E-05"
        ixy="3.57731733683862E-11"
        ixz="2.13056608443697E-11"
        iyy="3.41959117675973E-05"
        iyz="2.07855922549413E-06"
        izz="8.8093054111005E-06" />
    </inertial>
    <visual>
      <origin
        xyz="0 0 0"
        rpy="0 0 0" />
      <geometry>
        <mesh
          filename="package://my_robot/meshes/link_f_l.STL" />
      </geometry>
      <material
        name="">
        <color
          rgba="0.776470588235294 0.776470588235294 0.819607843137255 1" />
      </material>
    </visual>
    <collision>
      <origin
        xyz="0 0 0"
        rpy="0 0 0" />
      <geometry>
        <mesh
          filename="package://my_robot/meshes/link_f_l.STL" />
      </geometry>
    </collision>
  </link>
  <joint
    name="joint_f_l"
    type="revolute">
    <origin
      xyz="-0.11936 -0.03 -0.083652"
      rpy="1.5708 0 -0.0013373" />
    <parent
      link="base_link" />
    <child
      link="link_f_l" />
    <axis
      xyz="0 1 0" />
    <limit
      lower="0"
      upper="0"
      effort="0"
      velocity="0" />
  </joint>
  <link
    name="link_f_l_w">
    <inertial>
      <origin
        xyz="-3.40547867683227E-11 -3.49490128503938E-09 0.0193015459055756"
        rpy="0 0 0" />
      <mass
        value="50" />
      <inertia
        ixx="0.00328931016602001"
        ixy="3.88977840636905E-11"
        ixz="1.12234402425694E-11"
        iyy="0.00328931075597925"
        iyz="5.99468684940932E-11"
        izz="0.00610927992548664" />
    </inertial>
    <visual>
      <origin
        xyz="0 0 0"
        rpy="0 0 0" />
      <geometry>
        <mesh
          filename="package://my_robot/meshes/link_f_l_w.STL" />
      </geometry>
      <material
        name="">
        <color
          rgba="0.43921568627451 0.411764705882353 0.411764705882353 1" />
      </material>
    </visual>
    <collision>
      <origin
        xyz="0 0 0"
        rpy="0 0 0" />
      <geometry>
        <mesh
          filename="package://my_robot/meshes/link_f_l_w.STL" />
      </geometry>
    </collision>
  </link>
  <joint
    name="joint_f_l_w"
    type="continuous">
    <origin
      xyz="0 -0.0287 0.0315"
      rpy="0 0 -0.16944" />
    <parent
      link="link_f_l" />
    <child
      link="link_f_l_w" />
    <axis
      xyz="0 0 1" />
  </joint>
  <link
    name="link_l_w">
    <inertial>
      <origin
        xyz="1.93514776286596E-08 4.47823289839722E-08 0.0240491941638467"
        rpy="0 0 0" />
      <mass
        value="80" />
      <inertia
        ixx="0.0102180607960696"
        ixy="-6.26346556087745E-09"
        ixz="-1.29256158097415E-09"
        iyy="0.0102180458823884"
        iyz="-1.41431817132572E-08"
        izz="0.0189261335122509" />
    </inertial>
    <visual>
      <origin
        xyz="0 0 0"
        rpy="0 0 0" />
      <geometry>
        <mesh
          filename="package://my_robot/meshes/link_l_w.STL" />
      </geometry>
      <material
        name="">
        <color
          rgba="0.43921568627451 0.411764705882353 0.411764705882353 1" />
      </material>
    </visual>
    <collision>
      <origin
        xyz="0 0 0"
        rpy="0 0 0" />
      <geometry>
        <mesh
          filename="package://my_robot/meshes/link_l_w.STL" />
      </geometry>
    </collision>
  </link>
  <joint
    name="joint_l_w"
    type="continuous">
    <origin
      xyz="0.12954 -0.058 -0.093652"
      rpy="1.5708 -1.3692 0" />
    <parent
      link="base_link" />
    <child
      link="link_l_w" />
    <axis
      xyz="0 0 1" />
  </joint>
  <link
    name="link_r_w">
    <inertial>
      <origin
        xyz="1.9203058615469E-08 4.48012880405191E-08 0.0240491941603083"
        rpy="0 0 0" />
      <mass
        value="80" />
      <inertia
        ixx="0.0102180607714631"
        ixy="-6.26437820627074E-09"
        ixz="-1.30802623565512E-09"
        iyy="0.0102180459023867"
        iyz="-1.41420382114478E-08"
        izz="0.0189261335047578" />
    </inertial>
    <visual>
      <origin
        xyz="0 0 0"
        rpy="0 0 0" />
      <geometry>
        <mesh
          filename="package://my_robot/meshes/link_r_w.STL" />
      </geometry>
      <material
        name="">
        <color
          rgba="0.43921568627451 0.411764705882353 0.411764705882353 1" />
      </material>
    </visual>
    <collision>
      <origin
        xyz="0 0 0"
        rpy="0 0 0" />
      <geometry>
        <mesh
          filename="package://my_robot/meshes/link_r_w.STL" />
      </geometry>
    </collision>
  </link>
  <joint
    name="joint_r_w"
    type="continuous">
    <origin
      xyz="0.12954 0.058 -0.093652"
      rpy="1.5708 -0.72515 3.1416" />
    <parent
      link="base_link" />
    <child
      link="link_r_w" />
    <axis
      xyz="0 0 1" />
  </joint>
  <link
    name="link_chair">
    <inertial>
      <origin
        xyz="0.00795646634636779 0.010988413110798 4.54037801315437E-09"
        rpy="0 0 0" />
      <mass
        value="10" />
      <inertia
        ixx="1.13022448456005E-05"
        ixy="-3.02755555391797E-06"
        ixz="3.68116612603687E-11"
        iyy="1.18628128554467E-05"
        iyz="4.42797352311085E-11"
        izz="1.0803302211531E-05" />
    </inertial>
    <visual>
      <origin
        xyz="0 0 0"
        rpy="0 0 0" />
      <geometry>
        <mesh
          filename="package://my_robot/meshes/link_chair.STL" />
      </geometry>
      <material
        name="">
        <color
          rgba="0.698039215686274 0.698039215686274 0.698039215686274 1" />
      </material>
    </visual>
    <collision>
      <origin
        xyz="0 0 0"
        rpy="0 0 0" />
      <geometry>
        <mesh
          filename="package://my_robot/meshes/link_chair.STL" />
      </geometry>
    </collision>
  </link>
  <joint
    name="joint_chair"
    type="fixed">
    <origin
      xyz="0.12954 0 0"
      rpy="1.5708 0 0" />
    <parent
      link="base_link" />
    <child
      link="link_chair" />
    <axis
      xyz="0 0 0" />
  </joint>
  <link
    name="link_w">
    <inertial>
      <origin
        xyz="7.74741081895763E-08 0.0486768837592625 -7.50635454212136E-07"
        rpy="0 0 0" />
      <mass
        value="5" />
      <inertia
        ixx="7.86754554500572E-07"
        ixy="-2.23969797466759E-12"
        ixz="1.49194730377266E-11"
        iyy="7.9147029118932E-07"
        iyz="2.37604094505889E-11"
        izz="7.86744961862458E-07" />
    </inertial>
    <visual>
      <origin
        xyz="0 0 0"
        rpy="0 0 0" />
      <geometry>
        <mesh
          filename="package://my_robot/meshes/link_w.STL" />
      </geometry>
      <material
        name="">
        <color
          rgba="0.698039215686274 0.698039215686274 0.698039215686274 1" />
      </material>
    </visual>
    <collision>
      <origin
        xyz="0 0 0"
        rpy="0 0 0" />
      <geometry>
        <mesh
          filename="package://my_robot/meshes/link_w.STL" />
      </geometry>
    </collision>
  </link>
  <joint
    name="joint_w"
    type="fixed">
    <origin
      xyz="0.002429 0 -0.011517"
      rpy="1.9409 0.9276 0.45148" />
    <parent
      link="base_link" />
    <child
      link="link_w" />
    <axis
      xyz="0 0 0" />
  </joint>
</robot>