<sdf version='1.10'>
  <world name='car_world'>
    <physics name='1ms' type='ignored'>
      <max_step_size>0.0050000000000000001</max_step_size>
      <real_time_factor>1</real_time_factor>
      <real_time_update_rate>1000</real_time_update_rate>
    </physics>
    <plugin name='gz::sim::systems::Physics' filename='gz-sim-physics-system'/>
    <plugin name='gz::sim::systems::UserCommands' filename='gz-sim-user-commands-system'/>
    <plugin name='gz::sim::systems::SceneBroadcaster' filename='gz-sim-scene-broadcaster-system'/>
    <plugin name='gz::sim::systems::Imu' filename='gz-sim-imu-system'/>
    <plugin name='gz::sim::systems::Contact' filename='gz-sim-contact-system'/>
    <plugin name='gz::sim::systems::Sensors' filename='gz-sim-sensors-system'>
      <render_engine>ogre2</render_engine>
    </plugin>
    <gravity>0 0 -9.8000000000000007</gravity>
    <magnetic_field>5.5644999999999998e-06 2.2875799999999999e-05 -4.2388400000000002e-05</magnetic_field>
    <atmosphere type='adiabatic'/>
    <scene>
      <ambient>0.400000006 0.400000006 0.400000006 1</ambient>
      <background>0.699999988 0.699999988 0.699999988 1</background>
      <shadows>true</shadows>
    </scene>
    <model name='bush'>
      <pose>0 0 0 0 0 0</pose>
      <link name='link'>
        <visual name='bush_visual'>
          <pose>0 0 0.029999999999999999 0 0 0</pose>
          <geometry>
            <mesh>
              <uri>model://my_robot/meshes/bushes.STL</uri>
              <scale>0.0001 0.0001 0.0001</scale>
            </mesh>
          </geometry>
          <material>
            <ambient>0.100000001 0.5 0.100000001 1</ambient>
            <diffuse>0.300000012 0.699999988 0.300000012 1</diffuse>
            <specular>0.100000001 0.100000001 0.100000001 1</specular>
          </material>
        </visual>
        <pose>0 0 0 0 0 0</pose>
     
        <enable_wind>false</enable_wind>
      </link>
      <static>true</static>
      <self_collide>false</self_collide>
    </model>
    <model name='furrow'>
      <pose>0 0 0 0 0 0</pose>
      <link name='link'>
        <visual name='furrow_cylinder'>
          <pose>0 0 0 1.5708 -5.5511151231257827e-17 1.5708</pose>
          <geometry>
            <cylinder>
              <radius>0.029999999999999999</radius>
              <length>0.5</length>
            </cylinder>
          </geometry>
          <material>
            <ambient>0.400000006 0.300000012 0.100000001 1</ambient>
            <diffuse>0.5 0.400000006 0.200000003 1</diffuse>
            <specular>0.100000001 0.100000001 0.100000001 1</specular>
          </material>
        </visual>
        <visual name='furrow_front_sphere'>
          <pose>0.25 0 0 0 0 0</pose>
          <geometry>
            <sphere>
              <radius>0.029999999999999999</radius>
            </sphere>
          </geometry>
          <material>
            <ambient>0.400000006 0.300000012 0.100000001 1</ambient>
            <diffuse>0.5 0.400000006 0.200000003 1</diffuse>
            <specular>0.100000001 0.100000001 0.100000001 1</specular>
          </material>
        </visual>
        <visual name='furrow_rear_sphere'>
          <pose>-0.25 0 0 0 0 0</pose>
          <geometry>
            <sphere>
              <radius>0.029999999999999999</radius>
            </sphere>
          </geometry>
          <material>
            <ambient>0.400000006 0.300000012 0.100000001 1</ambient>
            <diffuse>0.5 0.400000006 0.200000003 1</diffuse>
            <specular>0.100000001 0.100000001 0.100000001 1</specular>
          </material>
        </visual>
        <pose>0 0 0 0 0 0</pose>

        <enable_wind>false</enable_wind>
      </link>
      <static>true</static>
      <self_collide>false</self_collide>
    </model>
    <model name='ground_plane_1'>
      <static>true</static>
      <link name='link'>
        <collision name='collision'>
          <geometry>
            <plane>
              <normal>0 0 1</normal>
              <size>1 1</size>
            </plane>
          </geometry>
          <surface>
            <friction>
              <ode/>
            </friction>
            <bounce/>
            <contact/>
          </surface>
        </collision>
        <visual name='visual'>
          <geometry>
            <plane>
              <normal>0 0 1</normal>
              <size>10 10</size>
            </plane>
          </geometry>
          <material>
            <diffuse>1 1 1 1</diffuse>
            <pbr>
              <metal>
                <albedo_map>model://my_robot/materials/textures/dirt_difuse.png</albedo_map>
                <normal_map>model://my_robot/materials/textures/dirt_normal.png</normal_map>
                <metalness>0.0</metalness>
                <roughness>0.8</roughness>
              </metal>
            </pbr>
          </material>
        </visual>
        <pose>0 0 0 0 0 0</pose>
   
        <enable_wind>false</enable_wind>
      </link>
      <pose>0 0 0 0 0 0</pose>
      <self_collide>false</self_collide>
    </model>
    <model name='ground_plane_2'>
      <static>true</static>
      <pose>0 10 0 0 0 0</pose>
      <link name='link'>
        <collision name='collision'>
          <geometry>
            <plane>
              <normal>0 0 1</normal>
              <size>1 1</size>
            </plane>
          </geometry>
          <surface>
            <friction>
              <ode/>
            </friction>
            <bounce/>
            <contact/>
          </surface>
        </collision>
        <visual name='visual'>
          <geometry>
            <plane>
              <normal>0 0 1</normal>
              <size>10 10</size>
            </plane>
          </geometry>
          <material>
            <diffuse>1 1 1 1</diffuse>
            <pbr>
              <metal>
                <albedo_map>model://my_robot/materials/textures/dirt_difuse.png</albedo_map>
                <normal_map>model://my_robot/materials/textures/dirt_normal.png</normal_map>
                <metalness>0.0</metalness>
                <roughness>0.8</roughness>
              </metal>
            </pbr>
          </material>
        </visual>
        <pose>0 0 0 0 0 0</pose>
     
        <enable_wind>false</enable_wind>
      </link>
      <self_collide>false</self_collide>
    </model>
    <model name='ground_plane_3'>
      <static>true</static>
      <pose>10 0 0 0 0 0</pose>
      <link name='link'>
        <collision name='collision'>
          <geometry>
            <plane>
              <normal>0 0 1</normal>
              <size>1 1</size>
            </plane>
          </geometry>
          <surface>
            <friction>
              <ode/>
            </friction>
            <bounce/>
            <contact/>
          </surface>
        </collision>
        <visual name='visual'>
          <geometry>
            <plane>
              <normal>0 0 1</normal>
              <size>10 10</size>
            </plane>
          </geometry>
          <material>
            <diffuse>1 1 1 1</diffuse>
            <pbr>
              <metal>
                <albedo_map>model://my_robot/materials/textures/dirt_difuse.png</albedo_map>
                <normal_map>model://my_robot/materials/textures/dirt_normal.png</normal_map>
                <metalness>0.0</metalness>
                <roughness>0.8</roughness>
              </metal>
            </pbr>
          </material>
        </visual>
        <pose>0 0 0 0 0 0</pose>
    
        <enable_wind>false</enable_wind>
      </link>
      <self_collide>false</self_collide>
    </model>
    <model name='ground_plane_4'>
      <static>true</static>
      <pose>-10 0 0 0 0 0</pose>
      <link name='link'>
        <collision name='collision'>
          <geometry>
            <plane>
              <normal>0 0 1</normal>
              <size>1 1</size>
            </plane>
          </geometry>
          <surface>
            <friction>
              <ode/>
            </friction>
            <bounce/>
            <contact/>
          </surface>
        </collision>
        <visual name='visual'>
          <geometry>
            <plane>
              <normal>0 0 1</normal>
              <size>10 10</size>
            </plane>
          </geometry>
          <material>
            <diffuse>1 1 1 1</diffuse>
            <pbr>
              <metal>
                <albedo_map>model://my_robot/materials/textures/dirt_difuse.png</albedo_map>
                <normal_map>model://my_robot/materials/textures/dirt_normal.png</normal_map>
                <metalness>0.0</metalness>
                <roughness>0.8</roughness>
              </metal>
            </pbr>
          </material>
        </visual>
        <pose>0 0 0 0 0 0</pose>
    
        <enable_wind>false</enable_wind>
      </link>
      <self_collide>false</self_collide>
    </model>
    <model name='ground_plane_5'>
      <static>true</static>
      <pose>0 -10 0 0 0 0</pose>
      <link name='link'>
        <collision name='collision'>
          <geometry>
            <plane>
              <normal>0 0 1</normal>
              <size>1 1</size>
            </plane>
          </geometry>
          <surface>
            <friction>
              <ode/>
            </friction>
            <bounce/>
            <contact/>
          </surface>
        </collision>
        <visual name='visual'>
          <geometry>
            <plane>
              <normal>0 0 1</normal>
              <size>10 10</size>
            </plane>
          </geometry>
          <material>
            <diffuse>1 1 1 1</diffuse>
            <pbr>
              <metal>
                <albedo_map>model://my_robot/materials/textures/dirt_difuse.png</albedo_map>
                <normal_map>model://my_robot/materials/textures/dirt_normal.png</normal_map>
                <metalness>0.0</metalness>
                <roughness>0.8</roughness>
              </metal>
            </pbr>
          </material>
        </visual>
        <pose>0 0 0 0 0 0</pose>
   
        <enable_wind>false</enable_wind>
      </link>
      <self_collide>false</self_collide>
    </model>
    <model name='ground_plane_6'>
      <static>true</static>
      <pose>10 10 0 0 0 0</pose>
      <link name='link'>
        <collision name='collision'>
          <geometry>
            <plane>
              <normal>0 0 1</normal>
              <size>1 1</size>
            </plane>
          </geometry>
          <surface>
            <friction>
              <ode/>
            </friction>
            <bounce/>
            <contact/>
          </surface>
        </collision>
        <visual name='visual'>
          <geometry>
            <plane>
              <normal>0 0 1</normal>
              <size>10 10</size>
            </plane>
          </geometry>
          <material>
            <diffuse>1 1 1 1</diffuse>
            <pbr>
              <metal>
                <albedo_map>model://my_robot/materials/textures/dirt_difuse.png</albedo_map>
                <normal_map>model://my_robot/materials/textures/dirt_normal.png</normal_map>
                <metalness>0.0</metalness>
                <roughness>0.8</roughness>
              </metal>
            </pbr>
          </material>
        </visual>
        <pose>0 0 0 0 0 0</pose>
   
        <enable_wind>false</enable_wind>
      </link>
      <self_collide>false</self_collide>
    </model>
    <model name='ground_plane_7'>
      <static>true</static>
      <pose>-10 10 0 0 0 0</pose>
      <link name='link'>
        <collision name='collision'>
          <geometry>
            <plane>
              <normal>0 0 1</normal>
              <size>1 1</size>
            </plane>
          </geometry>
          <surface>
            <friction>
              <ode/>
            </friction>
            <bounce/>
            <contact/>
          </surface>
        </collision>
        <visual name='visual'>
          <geometry>
            <plane>
              <normal>0 0 1</normal>
              <size>10 10</size>
            </plane>
          </geometry>
          <material>
            <diffuse>1 1 1 1</diffuse>
            <pbr>
              <metal>
                <albedo_map>model://my_robot/materials/textures/dirt_difuse.png</albedo_map>
                <normal_map>model://my_robot/materials/textures/dirt_normal.png</normal_map>
                <metalness>0.0</metalness>
                <roughness>0.8</roughness>
              </metal>
            </pbr>
          </material>
        </visual>
        <pose>0 0 0 0 0 0</pose>
   
        <enable_wind>false</enable_wind>
      </link>
      <self_collide>false</self_collide>
    </model>
    <model name='ground_plane_8'>
      <static>true</static>
      <pose>-10 -10 0 0 0 0</pose>
      <link name='link'>
        <collision name='collision'>
          <geometry>
            <plane>
              <normal>0 0 1</normal>
              <size>1 1</size>
            </plane>
          </geometry>
          <surface>
            <friction>
              <ode/>
            </friction>
            <bounce/>
            <contact/>
          </surface>
        </collision>
        <visual name='visual'>
          <geometry>
            <plane>
              <normal>0 0 1</normal>
              <size>10 10</size>
            </plane>
          </geometry>
          <material>
            <diffuse>1 1 1 1</diffuse>
            <pbr>
              <metal>
                <albedo_map>model://my_robot/materials/textures/dirt_difuse.png</albedo_map>
                <normal_map>model://my_robot/materials/textures/dirt_normal.png</normal_map>
                <metalness>0.0</metalness>
                <roughness>0.8</roughness>
              </metal>
            </pbr>
          </material>
        </visual>
        <pose>0 0 0 0 0 0</pose>
   
        <enable_wind>false</enable_wind>
      </link>
      <self_collide>false</self_collide>
    </model>
    <model name='ground_plane_9'>
      <static>true</static>
      <pose>10 -10 0 0 0 0</pose>
      <link name='link'>
        <collision name='collision'>
          <geometry>
            <plane>
              <normal>0 0 1</normal>
              <size>1 1</size>
            </plane>
          </geometry>
          <surface>
            <friction>
              <ode/>
            </friction>
            <bounce/>
            <contact/>
          </surface>
        </collision>
        <visual name='visual'>
          <geometry>
            <plane>
              <normal>0 0 1</normal>
              <size>10 10</size>
            </plane>
          </geometry>
          <material>
            <diffuse>1 1 1 1</diffuse>
            <pbr>
              <metal>
                <albedo_map>model://my_robot/materials/textures/dirt_difuse.png</albedo_map>
                <normal_map>model://my_robot/materials/textures/dirt_normal.png</normal_map>
                <metalness>0.0</metalness>
                <roughness>0.8</roughness>
              </metal>
            </pbr>
          </material>
        </visual>
        <pose>0 0 0 0 0 0</pose>
   
        <enable_wind>false</enable_wind>
      </link>
      <self_collide>false</self_collide>
    </model>
    <model name='my_robot'>
      <frame name='lidar_frame' attached_to='base_link'>
        <pose>-0.10000000000000001 0 0.10000000000000001 0 0 3.1415899999999999</pose>
      </frame>
      
      <pose>0.53986501693725586 0 0.19901137053966522 0 0 0</pose>
      <link name='base_link'>
        <sensor name='gpu_lidar' type='gpu_lidar'>
          <pose>-0.10000000000000001 0 0.10000000000000001 0 0 3.1415899999999999</pose>
          <topic>lidar</topic>
          <update_rate>10</update_rate>
          <enable_metrics>false</enable_metrics>
          <lidar>
            <scan>
              <horizontal>
                <samples>640</samples>
                <resolution>1</resolution>
                <min_angle>-1.396263</min_angle>
                <max_angle>1.396263</max_angle>
              </horizontal>
              <vertical>
                <samples>1</samples>
                <min_angle>0</min_angle>
                <max_angle>0</max_angle>
                <resolution>0.01</resolution>
              </vertical>
            </scan>
            <range>
              <min>0.080000000000000002</min>
              <max>10</max>
              <resolution>0.01</resolution>
            </range>
            <noise>
              <type>none</type>
              <mean>0</mean>
              <stddev>0</stddev>
            </noise>
            <visibility_mask>4294967295</visibility_mask>
          </lidar>
        </sensor>
        <sensor name='imu_sensor' type='imu'>
          <pose>0 0 0 0 0 0</pose>
          <topic>imu</topic>
          <update_rate>1</update_rate>
          <enable_metrics>false</enable_metrics>
          <imu>
            <orientation_reference_frame>
              <localization>CUSTOM</localization>
              <custom_rpy>0 0 0</custom_rpy>
              <grav_dir_x>1 0 0</grav_dir_x>
            </orientation_reference_frame>
            <angular_velocity>
              <x>
                <noise type='none'>
                  <mean>0</mean>
                  <stddev>0</stddev>
                  <bias_mean>0</bias_mean>
                  <bias_stddev>0</bias_stddev>
                  <dynamic_bias_stddev>0</dynamic_bias_stddev>
                  <dynamic_bias_correlation_time>0</dynamic_bias_correlation_time>
                  <precision>0</precision>
                </noise>
              </x>
              <y>
                <noise type='none'>
                  <mean>0</mean>
                  <stddev>0</stddev>
                  <bias_mean>0</bias_mean>
                  <bias_stddev>0</bias_stddev>
                  <dynamic_bias_stddev>0</dynamic_bias_stddev>
                  <dynamic_bias_correlation_time>0</dynamic_bias_correlation_time>
                  <precision>0</precision>
                </noise>
              </y>
              <z>
                <noise type='none'>
                  <mean>0</mean>
                  <stddev>0</stddev>
                  <bias_mean>0</bias_mean>
                  <bias_stddev>0</bias_stddev>
                  <dynamic_bias_stddev>0</dynamic_bias_stddev>
                  <dynamic_bias_correlation_time>0</dynamic_bias_correlation_time>
                  <precision>0</precision>
                </noise>
              </z>
            </angular_velocity>
            <linear_acceleration>
              <x>
                <noise type='none'>
                  <mean>0</mean>
                  <stddev>0</stddev>
                  <bias_mean>0</bias_mean>
                  <bias_stddev>0</bias_stddev>
                  <dynamic_bias_stddev>0</dynamic_bias_stddev>
                  <dynamic_bias_correlation_time>0</dynamic_bias_correlation_time>
                  <precision>0</precision>
                </noise>
              </x>
              <y>
                <noise type='none'>
                  <mean>0</mean>
                  <stddev>0</stddev>
                  <bias_mean>0</bias_mean>
                  <bias_stddev>0</bias_stddev>
                  <dynamic_bias_stddev>0</dynamic_bias_stddev>
                  <dynamic_bias_correlation_time>0</dynamic_bias_correlation_time>
                  <precision>0</precision>
                </noise>
              </y>
              <z>
                <noise type='none'>
                  <mean>0</mean>
                  <stddev>0</stddev>
                  <bias_mean>0</bias_mean>
                  <bias_stddev>0</bias_stddev>
                  <dynamic_bias_stddev>0</dynamic_bias_stddev>
                  <dynamic_bias_correlation_time>0</dynamic_bias_correlation_time>
                  <precision>0</precision>
                </noise>
              </z>
            </linear_acceleration>
            <enable_orientation>true</enable_orientation>
          </imu>
        </sensor>
        <pose>0 0 0 0 0 0</pose>
        <inertial>
          <pose>0.0058454205343183591 -0.033047754336371298 0.00040511309340032499 0 0 0</pose>
          <mass>515.10000000000002</mass>
          <inertia>
            <ixx>0</ixx>
            <ixy>0</ixy>
            <ixz>0</ixz>
            <iyy>0</iyy>
            <iyz>0</iyz>
            <izz>0</izz>
          </inertia>
        </inertial>
        <collision name='base_link_collision'>
          <pose>0 0 0 0 0 0</pose>
          <geometry>
            <mesh>
              <scale>1 1 1</scale>
              <uri>model://my_robot/meshes/base_link.STL</uri>
            </mesh>
          </geometry>
        </collision>
        <collision name='base_link_fixed_joint_lump__link_chair_collision_1'>
          <pose>0.12953999999999999 0 0 1.5708 0 0</pose>
          <geometry>
            <mesh>
              <scale>1 1 1</scale>
              <uri>model://my_robot/meshes/link_chair.STL</uri>
            </mesh>
          </geometry>
        </collision>
        <collision name='base_link_fixed_joint_lump__link_w_collision_2'>
          <pose>0.0024290000000000002 0 -0.011516999999999999 1.9409000000000003 0.92759999999999998 0.45148000000000005</pose>
          <geometry>
            <mesh>
              <scale>1 1 1</scale>
              <uri>model://my_robot/meshes/link_w.STL</uri>
            </mesh>
          </geometry>
        </collision>
        <visual name='base_link_visual'>
          <pose>0 0 0 0 0 0</pose>
          <geometry>
            <mesh>
              <scale>1 1 1</scale>
              <uri>model://my_robot/meshes/base_link.STL</uri>
            </mesh>
          </geometry>
          <material>
            <diffuse>0.715687513 0.720587492 0.720587492 1</diffuse>
            <ambient>0.715687513 0.720587492 0.720587492 1</ambient>
          </material>
        </visual>
        <visual name='base_link_fixed_joint_lump__link_chair_visual_1'>
          <pose>0.12953999999999999 0 0 1.5708 0 0</pose>
          <geometry>
            <mesh>
              <scale>1 1 1</scale>
              <uri>model://my_robot/meshes/link_chair.STL</uri>
            </mesh>
          </geometry>
          <material>
            <diffuse>0.872549057 0.872549057 0.872549057 1</diffuse>
            <ambient>0.872549057 0.872549057 0.872549057 1</ambient>
          </material>
        </visual>
        <visual name='base_link_fixed_joint_lump__link_w_visual_2'>
          <pose>0.0024290000000000002 0 -0.011516999999999999 1.9409000000000003 0.92759999999999998 0.45148000000000005</pose>
          <geometry>
            <mesh>
              <scale>1 1 1</scale>
              <uri>model://my_robot/meshes/link_w.STL</uri>
            </mesh>
          </geometry>
          <material>
            <diffuse>0.872549057 0.872549057 0.872549057 1</diffuse>
            <ambient>0.872549057 0.872549057 0.872549057 1</ambient>
          </material>
        </visual>
        <enable_wind>false</enable_wind>
      </link>
      <joint name='joint_f_l' type='revolute'>
        <pose>0 -2.7755575615628914e-17 3.4694469519536142e-18 0 0 0</pose>
        <parent>base_link</parent>
        <child>link_f_l</child>
        <axis>
          <xyz>0 1 0</xyz>
          <limit>
            <lower>0</lower>
            <upper>0</upper>
            <effort>0</effort>
            <velocity>0</velocity>
            <stiffness>100000000</stiffness>
            <dissipation>1</dissipation>
          </limit>
          <dynamics>
            <spring_reference>0</spring_reference>
            <spring_stiffness>0</spring_stiffness>
            <damping>0</damping>
            <friction>0</friction>
          </dynamics>
        </axis>
      </joint>
      <link name='link_f_l'>
        <pose>-0.11936000000000002 -0.029999999999999999 -0.08365200000000006 1.5708000000000002 1.0842021724855044e-19 -0.0013373</pose>
        <inertial>
          <pose>-2.8865797890853499e-08 -0.027726926623937699 0.015705756039529301 0 0 0</pose>
          <mass>30</mass>
          <inertia>
            <ixx>3.6463434644537301e-05</ixx>
            <ixy>3.5773173368386197e-11</ixy>
            <ixz>2.1305660844369701e-11</ixz>
            <iyy>3.4195911767597302e-05</iyy>
            <iyz>2.0785592254941299e-06</iyz>
            <izz>8.8093054111004995e-06</izz>
          </inertia>
        </inertial>
        <collision name='link_f_l_collision'>
          <pose>0 0 0 0 0 0</pose>
          <geometry>
            <mesh>
              <scale>1 1 1</scale>
              <uri>model://my_robot/meshes/link_f_l.STL</uri>
            </mesh>
          </geometry>
        </collision>
        <visual name='link_f_l_visual'>
          <pose>0 0 0 0 0 0</pose>
          <geometry>
            <mesh>
              <scale>1 1 1</scale>
              <uri>model://my_robot/meshes/link_f_l.STL</uri>
            </mesh>
          </geometry>
          <material>
            <diffuse>0.970588267 0.970588267 1 1</diffuse>
            <ambient>0.970588267 0.970588267 1 1</ambient>
          </material>
        </visual>
        <enable_wind>false</enable_wind>
      </link>
      <joint name='joint_f_l_w' type='revolute'>
        <pose>2.7755575615628914e-17 2.7755575615628914e-17 4.8572257327350599e-17 -1.9259299443872359e-34 1.3877787807814457e-17 -2.7755575615628914e-17</pose>
        <parent>link_f_l</parent>
        <child>link_f_l_w</child>
        <axis>
          <xyz>1.3877787807814457e-17 -1.9259299443872359e-34 1</xyz>
          <limit>
            <lower>-inf</lower>
            <upper>inf</upper>
            <effort>inf</effort>
            <velocity>inf</velocity>
            <stiffness>100000000</stiffness>
            <dissipation>1</dissipation>
          </limit>
          <dynamics>
            <spring_reference>0</spring_reference>
            <spring_stiffness>0</spring_stiffness>
            <damping>0</damping>
            <friction>0</friction>
          </dynamics>
        </axis>
      </joint>
      <link name='link_f_l_w'>
        <pose>-0.11940212479646445 -0.061499866412051671 -0.11235211570576703 1.5708000533669164 0.16943999999884585 -0.00133667158668803</pose>
        <inertial>
          <pose>-3.4054786768322697e-11 -3.4949012850393798e-09 0.0193015459055756 0 0 0</pose>
          <mass>50</mass>
          <inertia>
            <ixx>0.00328931016602001</ixx>
            <ixy>3.88977840636905e-11</ixy>
            <ixz>1.1223440242569399e-11</ixz>
            <iyy>0.0032893107559792498</iyy>
            <iyz>5.9946868494093202e-11</iyz>
            <izz>0.00610927992548664</izz>
          </inertia>
        </inertial>
        <collision name='link_f_l_w_collision'>
          <pose>0 0 0 0 0 0</pose>
          <geometry>
            <mesh>
              <scale>1 1 1</scale>
              <uri>model://my_robot/meshes/link_f_l_w.STL</uri>
            </mesh>
          </geometry>
        </collision>
        <visual name='link_f_l_w_visual'>
          <pose>0 0 0 0 0 0</pose>
          <geometry>
            <mesh>
              <scale>1 1 1</scale>
              <uri>model://my_robot/meshes/link_f_l_w.STL</uri>
            </mesh>
          </geometry>
          <material>
            <diffuse>0.549019635 0.514705896 0.514705896 1</diffuse>
            <ambient>0.549019635 0.514705896 0.514705896 1</ambient>
          </material>
        </visual>
        <enable_wind>false</enable_wind>
      </link>
      <joint name='joint_f_r' type='revolute'>
        <pose>1.3877787807814457e-17 0 3.4694469519536142e-18 0 0 0</pose>
        <parent>base_link</parent>
        <child>link_f_r</child>
        <axis>
          <xyz>0 1 0</xyz>
          <limit>
            <lower>0</lower>
            <upper>0</upper>
            <effort>0</effort>
            <velocity>0</velocity>
            <stiffness>100000000</stiffness>
            <dissipation>1</dissipation>
          </limit>
          <dynamics>
            <spring_reference>0</spring_reference>
            <spring_stiffness>0</spring_stiffness>
            <damping>0</damping>
            <friction>0</friction>
          </dynamics>
        </axis>
      </joint>
      <link name='link_f_r'>
        <pose>-0.11936000000000002 0.029999999999999999 -0.08365200000000006 1.5708000000000004 2.8644621397067027e-16 3.1402999999999994</pose>
        <inertial>
          <pose>-2.8865797960242501e-08 -0.027726926623937699 0.015705756039529201 0 0 0</pose>
          <mass>30</mass>
          <inertia>
            <ixx>3.6463434644537301e-05</ixx>
            <ixy>3.5773173367633902e-11</ixy>
            <ixz>2.13056608406061e-11</ixz>
            <iyy>3.41959117675972e-05</iyy>
            <iyz>2.0785592254941299e-06</iyz>
            <izz>8.8093054111004995e-06</izz>
          </inertia>
        </inertial>
        <collision name='link_f_r_collision'>
          <pose>0 0 0 0 0 0</pose>
          <geometry>
            <mesh>
              <scale>1 1 1</scale>
              <uri>model://my_robot/meshes/link_f_r.STL</uri>
            </mesh>
          </geometry>
        </collision>
        <visual name='link_f_r_visual'>
          <pose>0 0 0 0 0 0</pose>
          <geometry>
            <mesh>
              <scale>1 1 1</scale>
              <uri>model://my_robot/meshes/link_f_r.STL</uri>
            </mesh>
          </geometry>
          <material>
            <diffuse>0.970588267 0.970588267 1 1</diffuse>
            <ambient>0.970588267 0.970588267 1 1</ambient>
          </material>
        </visual>
        <enable_wind>false</enable_wind>
      </link>
      <joint name='joint_f_r_w' type='revolute'>
        <pose>-1.3877787807814457e-17 0 0 0 0 -5.5511151231257827e-17</pose>
        <parent>link_f_r</parent>
        <child>link_f_r_w</child>
        <axis>
          <xyz>0 0 -1</xyz>
          <limit>
            <lower>-inf</lower>
            <upper>inf</upper>
            <effort>inf</effort>
            <velocity>inf</velocity>
            <stiffness>100000000</stiffness>
            <dissipation>1</dissipation>
          </limit>
          <dynamics>
            <spring_reference>0</spring_reference>
            <spring_stiffness>0</spring_stiffness>
            <damping>0</damping>
            <friction>0</friction>
          </dynamics>
        </axis>
      </joint>
      <link name='link_f_r_w'>
        <pose>-0.11931928155953436 0.061499868261378224 -0.11235211570576716 1.5709129693639217 1.5392999997858978 3.1404165847180097</pose>
        <inertial>
          <pose>-3.4805047732788801e-11 -3.4951406491234799e-09 0.019301545905589398 0 0 0</pose>
          <mass>50</mass>
          <inertia>
            <ixx>0.0032893101660333699</ixx>
            <ixy>3.8900592014795497e-11</ixy>
            <ixz>1.1295439100500799e-11</ixz>
            <iyy>0.0032893107559765701</iyy>
            <iyz>5.9875460000761905e-11</iyz>
            <izz>0.0061092799254975298</izz>
          </inertia>
        </inertial>
        <collision name='link_f_r_w_collision'>
          <pose>0 0 0 0 0 0</pose>
          <geometry>
            <mesh>
              <scale>1 1 1</scale>
              <uri>model://my_robot/meshes/link_f_r_w.STL</uri>
            </mesh>
          </geometry>
        </collision>
        <visual name='link_f_r_w_visual'>
          <pose>0 0 0 0 0 0</pose>
          <geometry>
            <mesh>
              <scale>1 1 1</scale>
              <uri>model://my_robot/meshes/link_f_r_w.STL</uri>
            </mesh>
          </geometry>
          <material>
            <diffuse>0.549019635 0.514705896 0.514705896 1</diffuse>
            <ambient>0.549019635 0.514705896 0.514705896 1</ambient>
          </material>
        </visual>
        <enable_wind>false</enable_wind>
      </link>
      <joint name='joint_l_w' type='revolute'>
        <pose>-5.5511151231257827e-17 -2.7755575615628914e-17 4.163336342344337e-17 1.5407439555097887e-33 5.5511151231257827e-17 5.5511151231257827e-17</pose>
        <parent>base_link</parent>
        <child>link_l_w</child>
        <axis>
          <xyz>5.5511151231257827e-17 1.5407439555097887e-33 1</xyz>
          <limit>
            <lower>-inf</lower>
            <upper>inf</upper>
            <effort>inf</effort>
            <velocity>inf</velocity>
            <stiffness>100000000</stiffness>
            <dissipation>1</dissipation>
          </limit>
          <dynamics>
            <spring_reference>0</spring_reference>
            <spring_stiffness>0</spring_stiffness>
            <damping>0</damping>
            <friction>0</friction>
          </dynamics>
        </axis>
      </joint>
      <link name='link_l_w'>
        <pose>0.12953999999999999 -0.058000000000000003 -0.093651999999999944 1.5708000000000024 -1.3692000000000026 -2.7723197203030742e-15</pose>
        <inertial>
          <pose>1.93514776286596e-08 4.4782328983972197e-08 0.0240491941638467 0 0 0</pose>
          <mass>80</mass>
          <inertia>
            <ixx>0.0102180607960696</ixx>
            <ixy>-6.2634655608774498e-09</ixy>
            <ixz>-1.2925615809741501e-09</ixz>
            <iyy>0.0102180458823884</iyy>
            <iyz>-1.41431817132572e-08</iyz>
            <izz>0.018926133512250899</izz>
          </inertia>
        </inertial>
        <collision name='link_l_w_collision'>
          <pose>0 0 0 0 0 0</pose>
          <geometry>
            <mesh>
              <scale>1 1 1</scale>
              <uri>model://my_robot/meshes/link_l_w.STL</uri>
            </mesh>
          </geometry>
        </collision>
        <visual name='link_l_w_visual'>
          <pose>0 0 0 0 0 0</pose>
          <geometry>
            <mesh>
              <scale>1 1 1</scale>
              <uri>model://my_robot/meshes/link_l_w.STL</uri>
            </mesh>
          </geometry>
          <material>
            <diffuse>0.549019635 0.514705896 0.514705896 1</diffuse>
            <ambient>0.549019635 0.514705896 0.514705896 1</ambient>
          </material>
        </visual>
        <enable_wind>false</enable_wind>
      </link>
      <joint name='joint_r_w' type='revolute'>
        <pose>-2.7755575615628914e-17 -2.0816681711721685e-17 0 0 0 -5.5511151231257827e-17</pose>
        <parent>base_link</parent>
        <child>link_r_w</child>
        <axis>
          <xyz>0 0 1</xyz>
          <limit>
            <lower>-inf</lower>
            <upper>inf</upper>
            <effort>inf</effort>
            <velocity>inf</velocity>
            <stiffness>100000000</stiffness>
            <dissipation>1</dissipation>
          </limit>
          <dynamics>
            <spring_reference>0</spring_reference>
            <spring_stiffness>0</spring_stiffness>
            <damping>0</damping>
            <friction>0</friction>
          </dynamics>
        </axis>
      </joint>
      <link name='link_r_w'>
        <pose>0.12953999999999999 0.058000000000000003 -0.093651999999999958 1.5707999999999993 -0.72515000000000041 -3.1415853071795863</pose>
        <inertial>
          <pose>1.9203058615469001e-08 4.4801288040519103e-08 0.024049194160308301 0 0 0</pose>
          <mass>80</mass>
          <inertia>
            <ixx>0.010218060771463099</ixx>
            <ixy>-6.2643782062707401e-09</ixy>
            <ixz>-1.30802623565512e-09</ixz>
            <iyy>0.0102180459023867</iyy>
            <iyz>-1.41420382114478e-08</iyz>
            <izz>0.018926133504757799</izz>
          </inertia>
        </inertial>
        <collision name='link_r_w_collision'>
          <pose>0 0 0 0 0 0</pose>
          <geometry>
            <mesh>
              <scale>1 1 1</scale>
              <uri>model://my_robot/meshes/link_r_w.STL</uri>
            </mesh>
          </geometry>
        </collision>
        <visual name='link_r_w_visual'>
          <pose>0 0 0 0 0 0</pose>
          <geometry>
            <mesh>
              <scale>1 1 1</scale>
              <uri>model://my_robot/meshes/link_r_w.STL</uri>
            </mesh>
          </geometry>
          <material>
            <diffuse>0.549019635 0.514705896 0.514705896 1</diffuse>
            <ambient>0.549019635 0.514705896 0.514705896 1</ambient>
          </material>
        </visual>
        <enable_wind>false</enable_wind>
      </link>
      <frame name='joint_chair' attached_to='base_link'>
        <pose>0.12953999999999999 0 0 1.5708 0 0</pose>
      </frame>
      <frame name='link_chair' attached_to='joint_chair'>
        <pose>0 0 0 0 0 0</pose>
      </frame>
      <frame name='joint_w' attached_to='base_link'>
        <pose>0.0024290000000000002 0 -0.011516999999999999 1.9409000000000003 0.92759999999999998 0.45148000000000005</pose>
      </frame>
      <frame name='link_w' attached_to='joint_w'>
        <pose>0 0 0 0 0 0</pose>
      </frame>
      <plugin name='gz::sim::systems::DiffDrive' filename='gz-sim-diff-drive-system'>
        <left_joint>joint_f_l_w</left_joint>
        <right_joint>joint_f_r_w</right_joint>
        <wheel_separation>0.117</wheel_separation>
        <wheel_radius>0.5</wheel_radius>
        <odom_publish_frequency>1</odom_publish_frequency>
        <topic>/model/my_robot/cmd_vel</topic>
      </plugin>
      <plugin filename="gz-sim-triggered-publisher-system"
      name="gz::sim::systems::TriggeredPublisher">
  <input type="gz.msgs.Int32" topic="/keyboard/keypress">
      <match field="data">16777235</match>
  </input>
  <output type="gz.msgs.Twist" topic="/model/my_robot/cmd_vel">
      linear: {x: 0.5}, angular: {z: 0.0}
  </output>
</plugin>
      <static>false</static>
      <self_collide>false</self_collide>
    </model>
    <model name='bush_1'>
      <pose>-0.17153893968311185 0.0027062077410053287 0 0 0 0</pose>
      <link name='link'>
        <visual name='bush_visual'>
          <pose>0 0 0.029999999999999999 0 0 0</pose>
          <geometry>
            <mesh>
              <uri>model://my_robot/meshes/bushes.STL</uri>
              <scale>0.0001 0.0001 0.0001</scale>
            </mesh>
          </geometry>
          <material>
            <ambient>0.100000001 0.5 0.100000001 1</ambient>
            <diffuse>0.300000012 0.699999988 0.300000012 1</diffuse>
            <specular>0.100000001 0.100000001 0.100000001 1</specular>
          </material>
        </visual>
      </link>
      <static>true</static>
      <self_collide>false</self_collide>
    </model>
    <model name='bush_2'>
      <pose>0.16906244288713973 0.0082773095793112206 0 0 0 0</pose>
      <link name='link'>
        <visual name='bush_visual'>
          <pose>0 0 0.029999999999999999 0 0 0</pose>
          <geometry>
            <mesh>
              <uri>model://my_robot/meshes/bushes.STL</uri>
              <scale>0.0001 0.0001 0.0001</scale>
            </mesh>
          </geometry>
          <material>
            <ambient>0.100000001 0.5 0.100000001 1</ambient>
            <diffuse>0.300000012 0.699999988 0.300000012 1</diffuse>
            <specular>0.100000001 0.100000001 0.100000001 1</specular>
          </material>
        </visual>
      </link>
      <static>true</static>
      <self_collide>false</self_collide>
    </model>
    <model name='furrow_1'>
      <pose>-0.50996014103835108 -0.00081417053917920423 0 0 0 0</pose>
      <link name='link'>
        <visual name='furrow_cylinder'>
          <pose>0 0 0 1.5708 -5.5511151231257827e-17 1.5708</pose>
          <geometry>
            <cylinder>
              <radius>0.029999999999999999</radius>
              <length>0.5</length>
            </cylinder>
          </geometry>
          <material>
            <ambient>0.400000006 0.300000012 0.100000001 1</ambient>
            <diffuse>0.5 0.400000006 0.200000003 1</diffuse>
            <specular>0.100000001 0.100000001 0.100000001 1</specular>
          </material>
        </visual>
        <visual name='furrow_front_sphere'>
          <pose>0.25 0 0 0 0 0</pose>
          <geometry>
            <sphere>
              <radius>0.029999999999999999</radius>
            </sphere>
          </geometry>
          <material>
            <ambient>0.400000006 0.300000012 0.100000001 1</ambient>
            <diffuse>0.5 0.400000006 0.200000003 1</diffuse>
            <specular>0.100000001 0.100000001 0.100000001 1</specular>
          </material>
        </visual>
        <visual name='furrow_rear_sphere'>
          <pose>-0.25 0 0 0 0 0</pose>
          <geometry>
            <sphere>
              <radius>0.029999999999999999</radius>
            </sphere>
          </geometry>
          <material>
            <ambient>0.400000006 0.300000012 0.100000001 1</ambient>
            <diffuse>0.5 0.400000006 0.200000003 1</diffuse>
            <specular>0.100000001 0.100000001 0.100000001 1</specular>
          </material>
        </visual>
      </link>
      <static>true</static>
      <self_collide>false</self_collide>
    </model>
    <model name='furrow_2'>
      <pose>-1.0218471164315515 -0.0052556577745719313 0 0 0 0</pose>
      <link name='link'>
        <visual name='furrow_cylinder'>
          <pose>0 0 0 1.5708 -5.5511151231257827e-17 1.5708</pose>
          <geometry>
            <cylinder>
              <radius>0.029999999999999999</radius>
              <length>0.5</length>
            </cylinder>
          </geometry>
          <material>
            <ambient>0.400000006 0.300000012 0.100000001 1</ambient>
            <diffuse>0.5 0.400000006 0.200000003 1</diffuse>
            <specular>0.100000001 0.100000001 0.100000001 1</specular>
          </material>
        </visual>
        <visual name='furrow_front_sphere'>
          <pose>0.25 0 0 0 0 0</pose>
          <geometry>
            <sphere>
              <radius>0.029999999999999999</radius>
            </sphere>
          </geometry>
          <material>
            <ambient>0.400000006 0.300000012 0.100000001 1</ambient>
            <diffuse>0.5 0.400000006 0.200000003 1</diffuse>
            <specular>0.100000001 0.100000001 0.100000001 1</specular>
          </material>
        </visual>
        <visual name='furrow_rear_sphere'>
          <pose>-0.25 0 0 0 0 0</pose>
          <geometry>
            <sphere>
              <radius>0.029999999999999999</radius>
            </sphere>
          </geometry>
          <material>
            <ambient>0.400000006 0.300000012 0.100000001 1</ambient>
            <diffuse>0.5 0.400000006 0.200000003 1</diffuse>
            <specular>0.100000001 0.100000001 0.100000001 1</specular>
          </material>
        </visual>
      </link>
      <static>true</static>
      <self_collide>false</self_collide>
    </model>
    <model name='furrow_3'>
      <pose>-1.4780788717541689 0.016506762215053206 0 0 0 0</pose>
      <link name='link'>
        <visual name='furrow_cylinder'>
          <pose>0 0 0 1.5708 -5.5511151231257827e-17 1.5708</pose>
          <geometry>
            <cylinder>
              <radius>0.029999999999999999</radius>
              <length>0.5</length>
            </cylinder>
          </geometry>
          <material>
            <ambient>0.400000006 0.300000012 0.100000001 1</ambient>
            <diffuse>0.5 0.400000006 0.200000003 1</diffuse>
            <specular>0.100000001 0.100000001 0.100000001 1</specular>
          </material>
        </visual>
        <visual name='furrow_front_sphere'>
          <pose>0.25 0 0 0 0 0</pose>
          <geometry>
            <sphere>
              <radius>0.029999999999999999</radius>
            </sphere>
          </geometry>
          <material>
            <ambient>0.400000006 0.300000012 0.100000001 1</ambient>
            <diffuse>0.5 0.400000006 0.200000003 1</diffuse>
            <specular>0.100000001 0.100000001 0.100000001 1</specular>
          </material>
        </visual>
        <visual name='furrow_rear_sphere'>
          <pose>-0.25 0 0 0 0 0</pose>
          <geometry>
            <sphere>
              <radius>0.029999999999999999</radius>
            </sphere>
          </geometry>
          <material>
            <ambient>0.400000006 0.300000012 0.100000001 1</ambient>
            <diffuse>0.5 0.400000006 0.200000003 1</diffuse>
            <specular>0.100000001 0.100000001 0.100000001 1</specular>
          </material>
        </visual>
      </link>
      <static>true</static>
      <self_collide>false</self_collide>
    </model>
    <model name='bush_1_1'>
      <pose>-0.34804033215515168 0.0029453757742419207 0 0 0 0</pose>
      <link name='link'>
        <visual name='bush_visual'>
          <pose>0 0 0.029999999999999999 0 0 0</pose>
          <geometry>
            <mesh>
              <uri>model://my_robot/meshes/bushes.STL</uri>
              <scale>0.0001 0.0001 0.0001</scale>
            </mesh>
          </geometry>
          <material>
            <ambient>0.100000001 0.5 0.100000001 1</ambient>
            <diffuse>0.300000012 0.699999988 0.300000012 1</diffuse>
            <specular>0.100000001 0.100000001 0.100000001 1</specular>
          </material>
        </visual>
      </link>
      <static>true</static>
      <self_collide>false</self_collide>
    </model>
    <model name='bush_1_2'>
      <pose>-0.51820036786077672 0.0042207987427372862 0 0 0 0</pose>
      <link name='link'>
        <visual name='bush_visual'>
          <pose>0 0 0.029999999999999999 0 0 0</pose>
          <geometry>
            <mesh>
              <uri>model://my_robot/meshes/bushes.STL</uri>
              <scale>0.0001 0.0001 0.0001</scale>
            </mesh>
          </geometry>
          <material>
            <ambient>0.100000001 0.5 0.100000001 1</ambient>
            <diffuse>0.300000012 0.699999988 0.300000012 1</diffuse>
            <specular>0.100000001 0.100000001 0.100000001 1</specular>
          </material>
        </visual>
      </link>
      <static>true</static>
      <self_collide>false</self_collide>
    </model>
    <model name='bush_1_3'>
      <pose>-0.69709212976182244 0.00085929083025904074 0 0 0 0</pose>
      <link name='link'>
        <visual name='bush_visual'>
          <pose>0 0 0.029999999999999999 0 0 0</pose>
          <geometry>
            <mesh>
              <uri>model://my_robot/meshes/bushes.STL</uri>
              <scale>0.0001 0.0001 0.0001</scale>
            </mesh>
          </geometry>
          <material>
            <ambient>0.100000001 0.5 0.100000001 1</ambient>
            <diffuse>0.300000012 0.699999988 0.300000012 1</diffuse>
            <specular>0.100000001 0.100000001 0.100000001 1</specular>
          </material>
        </visual>
      </link>
      <static>true</static>
      <self_collide>false</self_collide>
    </model>
    <model name='bush_1_4'>
      <pose>-0.88458426369154775 -0.0071324162987536077 0 0 0 0</pose>
      <link name='link'>
        <visual name='bush_visual'>
          <pose>0 0 0.029999999999999999 0 0 0</pose>
          <geometry>
            <mesh>
              <uri>model://my_robot/meshes/bushes.STL</uri>
              <scale>0.0001 0.0001 0.0001</scale>
            </mesh>
          </geometry>
          <material>
            <ambient>0.100000001 0.5 0.100000001 1</ambient>
            <diffuse>0.300000012 0.699999988 0.300000012 1</diffuse>
            <specular>0.100000001 0.100000001 0.100000001 1</specular>
          </material>
        </visual>
      </link>
      <static>true</static>
      <self_collide>false</self_collide>
    </model>
    <model name='bush_1_5'>
      <pose>-1.0575720556234494 -0.0074525664830037419 0 0 0 0</pose>
      <link name='link'>
        <visual name='bush_visual'>
          <pose>0 0 0.029999999999999999 0 0 0</pose>
          <geometry>
            <mesh>
              <uri>model://my_robot/meshes/bushes.STL</uri>
              <scale>0.0001 0.0001 0.0001</scale>
            </mesh>
          </geometry>
          <material>
            <ambient>0.100000001 0.5 0.100000001 1</ambient>
            <diffuse>0.300000012 0.699999988 0.300000012 1</diffuse>
            <specular>0.100000001 0.100000001 0.100000001 1</specular>
          </material>
        </visual>
      </link>
      <static>true</static>
      <self_collide>false</self_collide>
    </model>
    <model name='bush_1_6'>
      <pose>-1.2238429569790448 -0.0084977724179413627 0 0 0 0</pose>
      <link name='link'>
        <visual name='bush_visual'>
          <pose>0 0 0.029999999999999999 0 0 0</pose>
          <geometry>
            <mesh>
              <uri>model://my_robot/meshes/bushes.STL</uri>
              <scale>0.0001 0.0001 0.0001</scale>
            </mesh>
          </geometry>
          <material>
            <ambient>0.100000001 0.5 0.100000001 1</ambient>
            <diffuse>0.300000012 0.699999988 0.300000012 1</diffuse>
            <specular>0.100000001 0.100000001 0.100000001 1</specular>
          </material>
        </visual>
      </link>
      <static>true</static>
      <self_collide>false</self_collide>
    </model>
    <model name='bush_1_7'>
      <pose>-1.3857608154042955 0.026876982490279921 0 0 0 0</pose>
      <link name='link'>
        <visual name='bush_visual'>
          <pose>0 0 0.029999999999999999 0 0 0</pose>
          <geometry>
            <mesh>
              <uri>model://my_robot/meshes/bushes.STL</uri>
              <scale>0.0001 0.0001 0.0001</scale>
            </mesh>
          </geometry>
          <material>
            <ambient>0.100000001 0.5 0.100000001 1</ambient>
            <diffuse>0.300000012 0.699999988 0.300000012 1</diffuse>
            <specular>0.100000001 0.100000001 0.100000001 1</specular>
          </material>
        </visual>
      </link>
      <static>true</static>
      <self_collide>false</self_collide>
    </model>
    <model name='bush_1_8'>
      <pose>-1.5481050242400065 0.010606105419408096 0 0 0 0</pose>
      <link name='link'>
        <visual name='bush_visual'>
          <pose>0 0 0.029999999999999999 0 0 0</pose>
          <geometry>
            <mesh>
              <uri>model://my_robot/meshes/bushes.STL</uri>
              <scale>0.0001 0.0001 0.0001</scale>
            </mesh>
          </geometry>
          <material>
            <ambient>0.100000001 0.5 0.100000001 1</ambient>
            <diffuse>0.300000012 0.699999988 0.300000012 1</diffuse>
            <specular>0.100000001 0.100000001 0.100000001 1</specular>
          </material>
        </visual>
      </link>
      <static>true</static>
      <self_collide>false</self_collide>
    </model>
    <model name='bush_1_9'>
      <pose>-1.715869054883443 0.022183053475411829 0 0 0 0</pose>
      <link name='link'>
        <visual name='bush_visual'>
          <pose>0 0 0.029999999999999999 0 0 0</pose>
          <geometry>
            <mesh>
              <uri>model://my_robot/meshes/bushes.STL</uri>
              <scale>0.0001 0.0001 0.0001</scale>
            </mesh>
          </geometry>
          <material>
            <ambient>0.100000001 0.5 0.100000001 1</ambient>
            <diffuse>0.300000012 0.699999988 0.300000012 1</diffuse>
            <specular>0.100000001 0.100000001 0.100000001 1</specular>
          </material>
        </visual>
      </link>
      <static>true</static>
      <self_collide>false</self_collide>
    </model>
    <light name='sun' type='directional'>
      <pose>0 0 10 0 0 0</pose>
      <cast_shadows>true</cast_shadows>
      <intensity>1</intensity>
      <direction>-0.5 0.10000000000000001 -0.90000000000000002</direction>
      <diffuse>0.800000012 0.800000012 0.800000012 1</diffuse>
      <specular>0.200000003 0.200000003 0.200000003 1</specular>
      <attenuation>
        <range>1000</range>
        <linear>0.01</linear>
        <constant>0.90000000000000002</constant>
        <quadratic>0.001</quadratic>
      </attenuation>
      <spot>
        <inner_angle>0</inner_angle>
        <outer_angle>0</outer_angle>
        <falloff>0</falloff>
      </spot>
    </light>
  </world>
</sdf>
