<sdf version='1.11'>
  <model name='my_robot'>
    <joint name='world_to_base' type='fixed'>
      <pose relative_to='__model__'>0 0 1 0 0 0</pose>
      <parent>world</parent>
      <child>base_link</child>
    </joint>
    <link name='base_link'>
      <pose relative_to='world_to_base'>0 0 0 0 0 0</pose>
      <inertial>
        <pose>0.002538429431178412 0 -0.0001117938264414677 0 0 0</pose>
        <mass>515.10000000000002</mass>
        <inertia>
          <ixx>0.31848885872807342</ixx>
          <ixy>-0.2089999999888433</ixy>
          <ixz>0.00044606368498925468</ixz>
          <iyy>0.99859486099191419</iyy>
          <iyz>0.00020478999613195639</iyz>
          <izz>1.1868291536638409</izz>
        </inertia>
      </inertial>
      <collision name='base_link_collision'>
        <pose>0 0 0 0 0 0</pose>
        <geometry>
          <mesh>
            <scale>1 1 1</scale>
            <uri>model://my_robot/meshes/base_link.STL</uri>
          </mesh>
        </geometry>
        <surface>
          <contact>
            <ode/>
          </contact>
          <friction>
            <ode/>
          </friction>
        </surface>
      </collision>
      <collision name='base_link_fixed_joint_lump__link_chair_collision_1'>
        <pose>0.12953999999999999 0 0 1.5708 0 0</pose>
        <geometry>
          <mesh>
            <scale>1 1 1</scale>
            <uri>model://my_robot/meshes/link_chair.STL</uri>
          </mesh>
        </geometry>
      </collision>
      <collision name='base_link_fixed_joint_lump__link_w_collision_2'>
        <pose>0.0024290000000000002 0 -0.011516999999999999 1.9409000000000003 0.92759999999999998 0.45148000000000005</pose>
        <geometry>
          <mesh>
            <scale>1 1 1</scale>
            <uri>model://my_robot/meshes/link_w.STL</uri>
          </mesh>
        </geometry>
      </collision>
      <visual name='base_link_visual'>
        <pose>0 0 0 0 0 0</pose>
        <geometry>
          <mesh>
            <scale>1 1 1</scale>
            <uri>model://my_robot/meshes/base_link.STL</uri>
          </mesh>
        </geometry>
        <material>
          <script>
            <name>Gazebo/Grey</name>
            <uri>file://media/materials/scripts/gazebo.material</uri>
          </script>
          <diffuse>0.715000033 0.719999969 0.719999969 1</diffuse>
          <ambient>0.715000033 0.719999969 0.719999969 1</ambient>
        </material>
      </visual>
      <visual name='base_link_fixed_joint_lump__link_chair_visual_1'>
        <pose>0.12953999999999999 0 0 1.5708 0 0</pose>
        <geometry>
          <mesh>
            <scale>1 1 1</scale>
            <uri>model://my_robot/meshes/link_chair.STL</uri>
          </mesh>
        </geometry>
        <material>
          <diffuse>0.872500002 0.872500002 0.872500002 1</diffuse>
          <ambient>0.872500002 0.872500002 0.872500002 1</ambient>
        </material>
      </visual>
      <visual name='base_link_fixed_joint_lump__link_w_visual_2'>
        <pose>0.0024290000000000002 0 -0.011516999999999999 1.9409000000000003 0.92759999999999998 0.45148000000000005</pose>
        <geometry>
          <mesh>
            <scale>1 1 1</scale>
            <uri>model://my_robot/meshes/link_w.STL</uri>
          </mesh>
        </geometry>
        <material>
          <diffuse>0.872500002 0.872500002 0.872500002 1</diffuse>
          <ambient>0.872500002 0.872500002 0.872500002 1</ambient>
        </material>
      </visual>
    </link>
    <joint name='joint_f_l' type='revolute'>
      <pose relative_to='base_link'>-0.11935999999999999 -0.029999999999999999 -0.083652000000000004 1.5708000000000002 3.2526065174565133e-19 -0.0013373</pose>
      <parent>base_link</parent>
      <child>link_f_l</child>
      <axis>
        <xyz>0 1 0</xyz>
        <limit>
          <lower>-1</lower>
          <upper>0</upper>
          <effort>100</effort>
          <velocity>1</velocity>
        </limit>
        <dynamics>
          <spring_reference>0</spring_reference>
          <spring_stiffness>0</spring_stiffness>
        </dynamics>
      </axis>
    </joint>
    <link name='link_f_l'>
      <pose relative_to='joint_f_l'>0 0 0 0 0 0</pose>
      <inertial>
        <pose>0 0 0 0 0 0</pose>
        <mass>30</mass>
        <inertia>
          <ixx>3.646e-05</ixx>
          <ixy>0</ixy>
          <ixz>0</ixz>
          <iyy>3.4190000000000003e-05</iyy>
          <iyz>2.0779999999999998e-06</iyz>
          <izz>8.8089999999999999e-06</izz>
        </inertia>
      </inertial>
      <collision name='link_f_l_collision'>
        <pose>0 0 0 0 0 0</pose>
        <geometry>
          <mesh>
            <scale>1 1 1</scale>
            <uri>model://my_robot/meshes/link_f_l.STL</uri>
          </mesh>
        </geometry>
      </collision>
      <visual name='link_f_l_visual'>
        <pose>0 0 0 0 0 0</pose>
        <geometry>
          <mesh>
            <scale>1 1 1</scale>
            <uri>model://my_robot/meshes/link_f_l.STL</uri>
          </mesh>
        </geometry>
        <material>
          <diffuse>0.970000029 0.970000029 1 1</diffuse>
          <ambient>0.970000029 0.970000029 1 1</ambient>
        </material>
      </visual>
    </link>
    <joint name='joint_f_l_w' type='revolute'>
      <pose relative_to='link_f_l'>0 -0.0287 0.0315 0 0 -0.0013373</pose>
      <parent>link_f_l</parent>
      <child>link_f_l_w</child>
      <axis>
        <xyz>0 0 1</xyz>
        <limit>
          <lower>-inf</lower>
          <upper>inf</upper>
        </limit>
        <dynamics>
          <spring_reference>0</spring_reference>
          <spring_stiffness>0</spring_stiffness>
        </dynamics>
      </axis>
    </joint>
    <link name='link_f_l_w'>
      <pose relative_to='joint_f_l_w'>0 0 0 0 0 0</pose>
      <inertial>
        <pose>0 0 0 0 0 0</pose>
        <mass>50</mass>
        <inertia>
          <ixx>0.0032889999999999998</ixx>
          <ixy>0</ixy>
          <ixz>0</ixz>
          <iyy>0.0032889999999999998</iyy>
          <iyz>0</iyz>
          <izz>0.0061089999999999998</izz>
        </inertia>
      </inertial>
      <collision name='link_f_l_w_collision'>
        <pose>0 0 0 0 0 0</pose>
        <geometry>
          <mesh>
            <scale>1 1 1</scale>
            <uri>model://my_robot/meshes/link_f_l_w.STL</uri>
          </mesh>
        </geometry>
      </collision>
      <visual name='link_f_l_w_visual'>
        <pose>0 0 0 0 0 0</pose>
        <geometry>
          <mesh>
            <scale>1 1 1</scale>
            <uri>model://my_robot/meshes/link_f_l_w.STL</uri>
          </mesh>
        </geometry>
        <material>
          <diffuse>0.548750043 0.513750017 0.513750017 1</diffuse>
          <ambient>0.548750043 0.513750017 0.513750017 1</ambient>
        </material>
      </visual>
    </link>
    <joint name='joint_f_r' type='revolute'>
      <pose relative_to='base_link'>-0.11935999999999999 0.029999999999999999 -0.083652000000000004 1.5708000000000002 0 3.1402999999999999</pose>
      <parent>base_link</parent>
      <child>link_f_r</child>
      <axis>
        <xyz>0 1 0</xyz>
        <limit>
          <lower>-1</lower>
          <upper>0</upper>
          <effort>100</effort>
          <velocity>1</velocity>
        </limit>
        <dynamics>
          <spring_reference>0</spring_reference>
          <spring_stiffness>0</spring_stiffness>
        </dynamics>
      </axis>
    </joint>
    <link name='link_f_r'>
      <pose relative_to='joint_f_r'>0 0 0 0 0 0</pose>
      <inertial>
        <pose>0 0 0 0 0 0</pose>
        <mass>30</mass>
        <inertia>
          <ixx>3.646e-05</ixx>
          <ixy>0</ixy>
          <ixz>0</ixz>
          <iyy>3.4190000000000003e-05</iyy>
          <iyz>2.0779999999999998e-06</iyz>
          <izz>8.8089999999999999e-06</izz>
        </inertia>
      </inertial>
      <collision name='link_f_r_collision'>
        <pose>0 0 0 0 0 0</pose>
        <geometry>
          <mesh>
            <scale>1 1 1</scale>
            <uri>model://my_robot/meshes/link_f_r.STL</uri>
          </mesh>
        </geometry>
      </collision>
      <visual name='link_f_r_visual'>
        <pose>0 0 0 0 0 0</pose>
        <geometry>
          <mesh>
            <scale>1 1 1</scale>
            <uri>model://my_robot/meshes/link_f_r.STL</uri>
          </mesh>
        </geometry>
        <material>
          <diffuse>0.970000029 0.970000029 1 1</diffuse>
          <ambient>0.970000029 0.970000029 1 1</ambient>
        </material>
      </visual>
    </link>
    <joint name='joint_f_r_w' type='revolute'>
      <pose relative_to='link_f_r'>0 -0.0287 0.0315 0 0 3.1402999999999999</pose>
      <parent>link_f_r</parent>
      <child>link_f_r_w</child>
      <axis>
        <xyz>0 0 1</xyz>
        <limit>
          <lower>-inf</lower>
          <upper>inf</upper>
        </limit>
        <dynamics>
          <spring_reference>0</spring_reference>
          <spring_stiffness>0</spring_stiffness>
        </dynamics>
      </axis>
    </joint>
    <link name='link_f_r_w'>
      <pose relative_to='joint_f_r_w'>0 0 0 0 0 0</pose>
      <inertial>
        <pose>0 0 0 0 0 0</pose>
        <mass>50</mass>
        <inertia>
          <ixx>0.0032889999999999998</ixx>
          <ixy>0</ixy>
          <ixz>0</ixz>
          <iyy>0.0032889999999999998</iyy>
          <iyz>0</iyz>
          <izz>0.0061089999999999998</izz>
        </inertia>
      </inertial>
      <collision name='link_f_r_w_collision'>
        <pose>0 0 0 0 0 0</pose>
        <geometry>
          <mesh>
            <scale>1 1 1</scale>
            <uri>model://my_robot/meshes/link_f_r_w.STL</uri>
          </mesh>
        </geometry>
      </collision>
      <visual name='link_f_r_w_visual'>
        <pose>0 0 0 0 0 0</pose>
        <geometry>
          <mesh>
            <scale>1 1 1</scale>
            <uri>model://my_robot/meshes/link_f_r_w.STL</uri>
          </mesh>
        </geometry>
        <material>
          <diffuse>0.548750043 0.513750017 0.513750017 1</diffuse>
          <ambient>0.548750043 0.513750017 0.513750017 1</ambient>
        </material>
      </visual>
    </link>
    <joint name='joint_l_w' type='revolute'>
      <pose relative_to='base_link'>0.12953999999999999 -0.058000000000000003 -0.093651999999999999 1.5707999999999998 -1.3692000000000004 -2.7723197203030547e-16</pose>
      <parent>base_link</parent>
      <child>link_l_w</child>
      <axis>
        <xyz>0 0 1</xyz>
        <limit>
          <lower>-inf</lower>
          <upper>inf</upper>
        </limit>
        <dynamics>
          <spring_reference>0</spring_reference>
          <spring_stiffness>0</spring_stiffness>
        </dynamics>
      </axis>
    </joint>
    <link name='link_l_w'>
      <pose relative_to='joint_l_w'>0 0 0 0 0 0</pose>
      <inertial>
        <pose>0 0 0 0 0 0</pose>
        <mass>80</mass>
        <inertia>
          <ixx>0.010218</ixx>
          <ixy>0</ixy>
          <ixz>0</ixz>
          <iyy>0.010218</iyy>
          <iyz>0</iyz>
          <izz>0.018925999999999998</izz>
        </inertia>
      </inertial>
      <collision name='link_l_w_collision'>
        <pose>0 0 0 0 0 0</pose>
        <geometry>
          <mesh>
            <scale>1 1 1</scale>
            <uri>model://my_robot/meshes/link_l_w.STL</uri>
          </mesh>
        </geometry>
      </collision>
      <visual name='link_l_w_visual'>
        <pose>0 0 0 0 0 0</pose>
        <geometry>
          <mesh>
            <scale>1 1 1</scale>
            <uri>model://my_robot/meshes/link_l_w.STL</uri>
          </mesh>
        </geometry>
        <material>
          <diffuse>0.548750043 0.513750017 0.513750017 1</diffuse>
          <ambient>0.548750043 0.513750017 0.513750017 1</ambient>
        </material>
      </visual>
    </link>
    <joint name='joint_r_w' type='revolute'>
      <pose relative_to='base_link'>0.12953999999999999 0.058000000000000003 -0.093651999999999999 1.5708 -0.72515000000000029 -3.1415853071795858</pose>
      <parent>base_link</parent>
      <child>link_r_w</child>
      <axis>
        <xyz>0 0 1</xyz>
        <limit>
          <lower>-inf</lower>
          <upper>inf</upper>
        </limit>
        <dynamics>
          <spring_reference>0</spring_reference>
          <spring_stiffness>0</spring_stiffness>
        </dynamics>
      </axis>
    </joint>
    <link name='link_r_w'>
      <pose relative_to='joint_r_w'>0 0 0 0 0 0</pose>
      <inertial>
        <pose>0 0 0 0 0 0</pose>
        <mass>80</mass>
        <inertia>
          <ixx>0.010218</ixx>
          <ixy>0</ixy>
          <ixz>0</ixz>
          <iyy>0.010218</iyy>
          <iyz>0</iyz>
          <izz>0.018925999999999998</izz>
        </inertia>
      </inertial>
      <collision name='link_r_w_collision'>
        <pose>0 0 0 0 0 0</pose>
        <geometry>
          <mesh>
            <scale>1 1 1</scale>
            <uri>model://my_robot/meshes/link_r_w.STL</uri>
          </mesh>
        </geometry>
      </collision>
      <visual name='link_r_w_visual'>
        <pose>0 0 0 0 0 0</pose>
        <geometry>
          <mesh>
            <scale>1 1 1</scale>
            <uri>model://my_robot/meshes/link_r_w.STL</uri>
          </mesh>
        </geometry>
        <material>
          <diffuse>0.548750043 0.513750017 0.513750017 1</diffuse>
          <ambient>0.548750043 0.513750017 0.513750017 1</ambient>
        </material>
      </visual>
    </link>
    <plugin name='gazebo_ros2_control' filename='libgazebo_ros2_control.so'>
      <parameters>/home/alexey/ros2_ws/install/my_robot/share/my_robot/config/controllers.yaml</parameters>
    </plugin>
    <frame name='joint_chair' attached_to='base_link'>
      <pose>0.12953999999999999 0 0 1.5708 0 0</pose>
    </frame>
    <frame name='link_chair' attached_to='joint_chair'>
      <pose>0 0 0 0 0 0</pose>
    </frame>
    <frame name='joint_w' attached_to='base_link'>
      <pose>0.0024290000000000002 0 -0.011516999999999999 1.9409000000000003 0.92759999999999998 0.45148000000000005</pose>
    </frame>
    <frame name='link_w' attached_to='joint_w'>
      <pose>0 0 0 0 0 0</pose>
    </frame>
  </model>
</sdf>
